<?xml version="1.0" ?>

<robot name="simple_manipulator" xmlns:xacro="http://www.ros.org/wiki/xacro">

  <material name="white">
    <color rgba="1 1 1 1"/>
  </material>

  <material name="red">
    <color rgba="1 0.5 0.5 1"/>
  </material>

  <material name="green">
    <color rgba="0.5 1 0.5 1"/>
  </material>

  <material name="blue">
    <color rgba="0.5 0.5 1 1"/>
  </material>

  <link name="base_footprint"/>

  <joint name="base_footprint_joint" type="fixed">
    <origin xyz="0 0 0.02" rpy="0 0 0"/>
    <parent link="base_footprint"/>
    <child link="base_link"/>
  </joint>

  <link name="base_link">
    <inertial>
      <mass value="5"/>
      <inertia ixx="0.013166666666666669" ixy="0.0" ixz="0.0" 
        iyy="0.013166666666666669" iyz="0.0" izz="0.025000000000000005"/>
    </inertial>
    <collision>
      <geometry>
        <cylinder length="0.04" radius="0.1"/>
      </geometry>
    </collision>
    <visual>
      <geometry>
        <cylinder length="0.04" radius="0.1"/>
      </geometry>
      <material name="white"/>
    </visual>
  </link>

  <link name="link_1">
    <inertial>
      <mass value="1"/>
      <inertia ixx="0.003358333333333334" ixy="0.0" ixz="0.0" 
        iyy="0.003358333333333334" iyz="0.0" izz="5e-05"/>
    </inertial>
    <collision>
      <geometry>
        <cylinder length="0.2" radius="0.01"/>
      </geometry>
    </collision>
    <visual>
      <geometry>
        <cylinder length="0.2" radius="0.01"/>
      </geometry>
      <material name="red"/>
    </visual>
  </link>

  <link name="link_2">
    <inertial>
      <mass value="1"/>
      <inertia ixx="0.0008583333333333335" ixy="0.0" ixz="0.0"
        iyy="0.0008583333333333335" iyz="0.0" izz="5e-05"/>
    </inertial>
    <collision>
      <origin xyz="0 0 0.05" rpy="0 0 0"/>
      <geometry>
        <cylinder length="0.1" radius="0.01"/>
      </geometry>
    </collision>
    <visual>
      <origin xyz="0 0 0.05" rpy="0 0 0"/>
      <geometry>
        <cylinder length="0.1" radius="0.01"/>
      </geometry>
      <material name="green"/>
    </visual>
  </link>

  <link name="link_3">
    <inertial>
      <mass value="1"/>
      <inertia ixx="0.0008583333333333335" ixy="0.0" ixz="0.0"
        iyy="0.0008583333333333335" iyz="0.0" izz="5e-05"/>
    </inertial>
    <collision>
      <origin xyz="0 0 0.05" rpy="0 0 0"/>
      <geometry>
        <cylinder length="0.1" radius="0.01"/>
      </geometry>
    </collision>
    <visual>
      <origin xyz="0 0 0.05" rpy="0 0 0"/>
      <geometry>
        <cylinder length="0.1" radius="0.01"/>
      </geometry>
      <material name="blue"/>
    </visual>
  </link>

  <joint name="link_1_joint" type="revolute">
    <origin xyz="0 0 0.1" rpy="0 0 0"/>
    <parent link="base_link"/>
    <child link="link_1"/>
    <axis rpy="0 0 0" xyz="0 0 1"/>
    <limit lower="-1.5708" upper="1.5708" effort="100" velocity="1"/>
  </joint>

  <joint name="link_2_joint" type="revolute">
    <origin xyz="0 0 0.1" rpy="1.5708 0 0"/>
    <parent link="link_1"/>
    <child link="link_2"/>
    <axis rpy="0 0 0" xyz="1 0 0"/>
    <limit lower="-1.5708" upper="1.5708" effort="100" velocity="1"/>
  </joint>

  <joint name="link_3_joint" type="revolute">
    <origin xyz="0 0 0.1" rpy="1.5708 0 0"/>
    <parent link="link_2"/>
    <child link="link_3"/>
    <axis rpy="0 0 0" xyz="0 1 0"/>
    <limit lower="-1.5708" upper="1.5708" effort="100" velocity="1"/>
  </joint>

</robot>
